[2021-12-01 22:31:07,424] {taskinstance.py:1035} INFO - Dependencies all met for <TaskInstance: my_sample_dag.s3_bucket_dag_create manual__2021-12-01T22:31:06.300359+00:00 [queued]>
[2021-12-01 22:31:07,434] {taskinstance.py:1035} INFO - Dependencies all met for <TaskInstance: my_sample_dag.s3_bucket_dag_create manual__2021-12-01T22:31:06.300359+00:00 [queued]>
[2021-12-01 22:31:07,434] {taskinstance.py:1241} INFO - 
--------------------------------------------------------------------------------
[2021-12-01 22:31:07,434] {taskinstance.py:1242} INFO - Starting attempt 1 of 1
[2021-12-01 22:31:07,434] {taskinstance.py:1243} INFO - 
--------------------------------------------------------------------------------
[2021-12-01 22:31:07,444] {taskinstance.py:1262} INFO - Executing <Task(S3CreateBucketOperator): s3_bucket_dag_create> on 2021-12-01 22:31:06.300359+00:00
[2021-12-01 22:31:07,449] {standard_task_runner.py:52} INFO - Started process 1718 to run task
[2021-12-01 22:31:07,452] {standard_task_runner.py:76} INFO - Running: ['***', 'tasks', 'run', 'my_sample_dag', 's3_bucket_dag_create', 'manual__2021-12-01T22:31:06.300359+00:00', '--job-id', '90', '--raw', '--subdir', 'DAGS_FOLDER/test_dag.py', '--cfg-path', '/tmp/tmpv7674r9t', '--error-file', '/tmp/tmpclarp1ue']
[2021-12-01 22:31:07,452] {standard_task_runner.py:77} INFO - Job 90: Subtask s3_bucket_dag_create
[2021-12-01 22:31:07,493] {logging_mixin.py:109} INFO - Running <TaskInstance: my_sample_dag.s3_bucket_dag_create manual__2021-12-01T22:31:06.300359+00:00 [running]> on host 2227579f6dd3
[2021-12-01 22:31:07,536] {taskinstance.py:1429} INFO - Exporting the following env vars:
AIRFLOW_CTX_DAG_OWNER=pipis
AIRFLOW_CTX_DAG_ID=my_sample_dag
AIRFLOW_CTX_TASK_ID=s3_bucket_dag_create
AIRFLOW_CTX_EXECUTION_DATE=2021-12-01T22:31:06.300359+00:00
AIRFLOW_CTX_DAG_RUN_ID=manual__2021-12-01T22:31:06.300359+00:00
[2021-12-01 22:31:07,537] {base_aws.py:401} INFO - Airflow Connection: aws_conn_id=aws_default
[2021-12-01 22:31:07,545] {base_aws.py:424} WARNING - Unable to use Airflow Connection for credentials.
[2021-12-01 22:31:07,546] {base_aws.py:425} INFO - Fallback on boto3 credential strategy
[2021-12-01 22:31:07,546] {base_aws.py:430} INFO - Creating session using boto3 credential strategy region_name=us-east-1
[2021-12-01 22:31:07,556] {warnings.py:110} WARNING - /home/***/.local/lib/python3.7/site-packages/***/providers/amazon/aws/hooks/base_aws.py:494: DeprecationWarning: client_type is deprecated. Set client_type from class attribute.
  return self.get_client_type(self.client_type, region_name=self.region_name)

[2021-12-01 22:31:09,597] {taskinstance.py:1703} ERROR - Task failed with exception
Traceback (most recent call last):
  File "/home/airflow/.local/lib/python3.7/site-packages/airflow/models/taskinstance.py", line 1332, in _run_raw_task
    self._execute_task_with_callbacks(context)
  File "/home/airflow/.local/lib/python3.7/site-packages/airflow/models/taskinstance.py", line 1458, in _execute_task_with_callbacks
    result = self._execute_task(context, self.task)
  File "/home/airflow/.local/lib/python3.7/site-packages/airflow/models/taskinstance.py", line 1514, in _execute_task
    result = execute_callable(context=context)
  File "/home/airflow/.local/lib/python3.7/site-packages/airflow/providers/amazon/aws/operators/s3_bucket.py", line 63, in execute
    if not s3_hook.check_for_bucket(self.bucket_name):
  File "/home/airflow/.local/lib/python3.7/site-packages/airflow/providers/amazon/aws/hooks/s3.py", line 62, in wrapper
    return func(*bound_args.args, **bound_args.kwargs)
  File "/home/airflow/.local/lib/python3.7/site-packages/airflow/providers/amazon/aws/hooks/s3.py", line 160, in check_for_bucket
    self.get_conn().head_bucket(Bucket=bucket_name)
  File "/home/airflow/.local/lib/python3.7/site-packages/botocore/client.py", line 388, in _api_call
    return self._make_api_call(operation_name, kwargs)
  File "/home/airflow/.local/lib/python3.7/site-packages/botocore/client.py", line 695, in _make_api_call
    operation_model, request_dict, request_context)
  File "/home/airflow/.local/lib/python3.7/site-packages/botocore/client.py", line 714, in _make_request
    return self._endpoint.make_request(operation_model, request_dict)
  File "/home/airflow/.local/lib/python3.7/site-packages/botocore/endpoint.py", line 102, in make_request
    return self._send_request(request_dict, operation_model)
  File "/home/airflow/.local/lib/python3.7/site-packages/botocore/endpoint.py", line 132, in _send_request
    request = self.create_request(request_dict, operation_model)
  File "/home/airflow/.local/lib/python3.7/site-packages/botocore/endpoint.py", line 116, in create_request
    operation_name=operation_model.name)
  File "/home/airflow/.local/lib/python3.7/site-packages/botocore/hooks.py", line 357, in emit
    return self._emitter.emit(aliased_event_name, **kwargs)
  File "/home/airflow/.local/lib/python3.7/site-packages/botocore/hooks.py", line 228, in emit
    return self._emit(event_name, kwargs)
  File "/home/airflow/.local/lib/python3.7/site-packages/botocore/hooks.py", line 211, in _emit
    response = handler(**kwargs)
  File "/home/airflow/.local/lib/python3.7/site-packages/botocore/signers.py", line 93, in handler
    return self.sign(operation_name, request)
  File "/home/airflow/.local/lib/python3.7/site-packages/botocore/signers.py", line 165, in sign
    auth.add_auth(request)
  File "/home/airflow/.local/lib/python3.7/site-packages/botocore/auth.py", line 378, in add_auth
    raise NoCredentialsError()
botocore.exceptions.NoCredentialsError: Unable to locate credentials
[2021-12-01 22:31:09,610] {taskinstance.py:1280} INFO - Marking task as FAILED. dag_id=my_sample_dag, task_id=s3_bucket_dag_create, execution_date=20211201T223106, start_date=20211201T223107, end_date=20211201T223109
[2021-12-01 22:31:09,624] {standard_task_runner.py:91} ERROR - Failed to execute job 90 for task s3_bucket_dag_create
Traceback (most recent call last):
  File "/home/airflow/.local/lib/python3.7/site-packages/airflow/task/task_runner/standard_task_runner.py", line 85, in _start_by_fork
    args.func(args, dag=self.dag)
  File "/home/airflow/.local/lib/python3.7/site-packages/airflow/cli/cli_parser.py", line 48, in command
    return func(*args, **kwargs)
  File "/home/airflow/.local/lib/python3.7/site-packages/airflow/utils/cli.py", line 92, in wrapper
    return f(*args, **kwargs)
  File "/home/airflow/.local/lib/python3.7/site-packages/airflow/cli/commands/task_command.py", line 292, in task_run
    _run_task_by_selected_method(args, dag, ti)
  File "/home/airflow/.local/lib/python3.7/site-packages/airflow/cli/commands/task_command.py", line 107, in _run_task_by_selected_method
    _run_raw_task(args, ti)
  File "/home/airflow/.local/lib/python3.7/site-packages/airflow/cli/commands/task_command.py", line 184, in _run_raw_task
    error_file=args.error_file,
  File "/home/airflow/.local/lib/python3.7/site-packages/airflow/utils/session.py", line 70, in wrapper
    return func(*args, session=session, **kwargs)
  File "/home/airflow/.local/lib/python3.7/site-packages/airflow/models/taskinstance.py", line 1332, in _run_raw_task
    self._execute_task_with_callbacks(context)
  File "/home/airflow/.local/lib/python3.7/site-packages/airflow/models/taskinstance.py", line 1458, in _execute_task_with_callbacks
    result = self._execute_task(context, self.task)
  File "/home/airflow/.local/lib/python3.7/site-packages/airflow/models/taskinstance.py", line 1514, in _execute_task
    result = execute_callable(context=context)
  File "/home/airflow/.local/lib/python3.7/site-packages/airflow/providers/amazon/aws/operators/s3_bucket.py", line 63, in execute
    if not s3_hook.check_for_bucket(self.bucket_name):
  File "/home/airflow/.local/lib/python3.7/site-packages/airflow/providers/amazon/aws/hooks/s3.py", line 62, in wrapper
    return func(*bound_args.args, **bound_args.kwargs)
  File "/home/airflow/.local/lib/python3.7/site-packages/airflow/providers/amazon/aws/hooks/s3.py", line 160, in check_for_bucket
    self.get_conn().head_bucket(Bucket=bucket_name)
  File "/home/airflow/.local/lib/python3.7/site-packages/botocore/client.py", line 388, in _api_call
    return self._make_api_call(operation_name, kwargs)
  File "/home/airflow/.local/lib/python3.7/site-packages/botocore/client.py", line 695, in _make_api_call
    operation_model, request_dict, request_context)
  File "/home/airflow/.local/lib/python3.7/site-packages/botocore/client.py", line 714, in _make_request
    return self._endpoint.make_request(operation_model, request_dict)
  File "/home/airflow/.local/lib/python3.7/site-packages/botocore/endpoint.py", line 102, in make_request
    return self._send_request(request_dict, operation_model)
  File "/home/airflow/.local/lib/python3.7/site-packages/botocore/endpoint.py", line 132, in _send_request
    request = self.create_request(request_dict, operation_model)
  File "/home/airflow/.local/lib/python3.7/site-packages/botocore/endpoint.py", line 116, in create_request
    operation_name=operation_model.name)
  File "/home/airflow/.local/lib/python3.7/site-packages/botocore/hooks.py", line 357, in emit
    return self._emitter.emit(aliased_event_name, **kwargs)
  File "/home/airflow/.local/lib/python3.7/site-packages/botocore/hooks.py", line 228, in emit
    return self._emit(event_name, kwargs)
  File "/home/airflow/.local/lib/python3.7/site-packages/botocore/hooks.py", line 211, in _emit
    response = handler(**kwargs)
  File "/home/airflow/.local/lib/python3.7/site-packages/botocore/signers.py", line 93, in handler
    return self.sign(operation_name, request)
  File "/home/airflow/.local/lib/python3.7/site-packages/botocore/signers.py", line 165, in sign
    auth.add_auth(request)
  File "/home/airflow/.local/lib/python3.7/site-packages/botocore/auth.py", line 378, in add_auth
    raise NoCredentialsError()
botocore.exceptions.NoCredentialsError: Unable to locate credentials
[2021-12-01 22:31:09,671] {local_task_job.py:154} INFO - Task exited with return code 1
[2021-12-01 22:31:09,701] {local_task_job.py:264} INFO - 0 downstream tasks scheduled from follow-on schedule check
