[2021-12-01 14:36:20,352] {taskinstance.py:1035} INFO - Dependencies all met for <TaskInstance: FrequencyCount.init manual__2021-12-01T14:25:26.630202+00:00 [queued]>
[2021-12-01 14:36:20,363] {taskinstance.py:1035} INFO - Dependencies all met for <TaskInstance: FrequencyCount.init manual__2021-12-01T14:25:26.630202+00:00 [queued]>
[2021-12-01 14:36:20,363] {taskinstance.py:1241} INFO - 
--------------------------------------------------------------------------------
[2021-12-01 14:36:20,363] {taskinstance.py:1242} INFO - Starting attempt 4 of 4
[2021-12-01 14:36:20,363] {taskinstance.py:1243} INFO - 
--------------------------------------------------------------------------------
[2021-12-01 14:36:20,377] {taskinstance.py:1262} INFO - Executing <Task(InitOperator): init> on 2021-12-01 14:25:26.630202+00:00
[2021-12-01 14:36:20,384] {standard_task_runner.py:52} INFO - Started process 77 to run task
[2021-12-01 14:36:20,386] {standard_task_runner.py:76} INFO - Running: ['***', 'tasks', 'run', 'FrequencyCount', 'init', 'manual__2021-12-01T14:25:26.630202+00:00', '--job-id', '36', '--raw', '--subdir', 'DAGS_FOLDER/mapred.py', '--cfg-path', '/tmp/tmp40f0ajes', '--error-file', '/tmp/tmpcj6mx6rx']
[2021-12-01 14:36:20,387] {standard_task_runner.py:77} INFO - Job 36: Subtask init
[2021-12-01 14:36:20,421] {logging_mixin.py:109} INFO - Running <TaskInstance: FrequencyCount.init manual__2021-12-01T14:25:26.630202+00:00 [running]> on host 68953790a869
[2021-12-01 14:36:20,457] {taskinstance.py:1429} INFO - Exporting the following env vars:
AIRFLOW_CTX_DAG_OWNER=***
AIRFLOW_CTX_DAG_ID=FrequencyCount
AIRFLOW_CTX_TASK_ID=init
AIRFLOW_CTX_EXECUTION_DATE=2021-12-01T14:25:26.630202+00:00
AIRFLOW_CTX_DAG_RUN_ID=manual__2021-12-01T14:25:26.630202+00:00
[2021-12-01 14:36:20,470] {logging_mixin.py:109} INFO - Directory b'***-worker.pid\n***.cfg\ndags\nlogs\nplugins\nwebserver_config.py\n'
[2021-12-01 14:36:20,470] {taskinstance.py:1703} ERROR - Task failed with exception
Traceback (most recent call last):
  File "/home/airflow/.local/lib/python3.7/site-packages/airflow/models/taskinstance.py", line 1332, in _run_raw_task
    self._execute_task_with_callbacks(context)
  File "/home/airflow/.local/lib/python3.7/site-packages/airflow/models/taskinstance.py", line 1458, in _execute_task_with_callbacks
    result = self._execute_task(context, self.task)
  File "/home/airflow/.local/lib/python3.7/site-packages/airflow/models/taskinstance.py", line 1514, in _execute_task
    result = execute_callable(context=context)
  File "/opt/airflow/plugins/init_operator.py", line 49, in execute
    with open(self.data_path, "r") as file:
FileNotFoundError: [Errno 2] No such file or directory: './dags/tweets.csv'
[2021-12-01 14:36:20,483] {taskinstance.py:1280} INFO - Marking task as FAILED. dag_id=FrequencyCount, task_id=init, execution_date=20211201T142526, start_date=20211201T143620, end_date=20211201T143620
[2021-12-01 14:36:20,496] {standard_task_runner.py:91} ERROR - Failed to execute job 36 for task init
Traceback (most recent call last):
  File "/home/airflow/.local/lib/python3.7/site-packages/airflow/task/task_runner/standard_task_runner.py", line 85, in _start_by_fork
    args.func(args, dag=self.dag)
  File "/home/airflow/.local/lib/python3.7/site-packages/airflow/cli/cli_parser.py", line 48, in command
    return func(*args, **kwargs)
  File "/home/airflow/.local/lib/python3.7/site-packages/airflow/utils/cli.py", line 92, in wrapper
    return f(*args, **kwargs)
  File "/home/airflow/.local/lib/python3.7/site-packages/airflow/cli/commands/task_command.py", line 292, in task_run
    _run_task_by_selected_method(args, dag, ti)
  File "/home/airflow/.local/lib/python3.7/site-packages/airflow/cli/commands/task_command.py", line 107, in _run_task_by_selected_method
    _run_raw_task(args, ti)
  File "/home/airflow/.local/lib/python3.7/site-packages/airflow/cli/commands/task_command.py", line 184, in _run_raw_task
    error_file=args.error_file,
  File "/home/airflow/.local/lib/python3.7/site-packages/airflow/utils/session.py", line 70, in wrapper
    return func(*args, session=session, **kwargs)
  File "/home/airflow/.local/lib/python3.7/site-packages/airflow/models/taskinstance.py", line 1332, in _run_raw_task
    self._execute_task_with_callbacks(context)
  File "/home/airflow/.local/lib/python3.7/site-packages/airflow/models/taskinstance.py", line 1458, in _execute_task_with_callbacks
    result = self._execute_task(context, self.task)
  File "/home/airflow/.local/lib/python3.7/site-packages/airflow/models/taskinstance.py", line 1514, in _execute_task
    result = execute_callable(context=context)
  File "/opt/airflow/plugins/init_operator.py", line 49, in execute
    with open(self.data_path, "r") as file:
FileNotFoundError: [Errno 2] No such file or directory: './dags/tweets.csv'
[2021-12-01 14:36:20,518] {local_task_job.py:154} INFO - Task exited with return code 1
[2021-12-01 14:36:20,600] {local_task_job.py:264} INFO - 0 downstream tasks scheduled from follow-on schedule check
