[2021-12-01 22:35:23,288] {taskinstance.py:1035} INFO - Dependencies all met for <TaskInstance: my_sample_dag.check_s3_for_file_in_s3 manual__2021-12-01T22:35:21.958244+00:00 [queued]>
[2021-12-01 22:35:23,298] {taskinstance.py:1035} INFO - Dependencies all met for <TaskInstance: my_sample_dag.check_s3_for_file_in_s3 manual__2021-12-01T22:35:21.958244+00:00 [queued]>
[2021-12-01 22:35:23,298] {taskinstance.py:1241} INFO - 
--------------------------------------------------------------------------------
[2021-12-01 22:35:23,298] {taskinstance.py:1242} INFO - Starting attempt 1 of 1
[2021-12-01 22:35:23,298] {taskinstance.py:1243} INFO - 
--------------------------------------------------------------------------------
[2021-12-01 22:35:23,308] {taskinstance.py:1262} INFO - Executing <Task(S3KeySensor): check_s3_for_file_in_s3> on 2021-12-01 22:35:21.958244+00:00
[2021-12-01 22:35:23,313] {standard_task_runner.py:52} INFO - Started process 1908 to run task
[2021-12-01 22:35:23,316] {standard_task_runner.py:76} INFO - Running: ['***', 'tasks', 'run', 'my_sample_dag', 'check_s3_for_file_in_s3', 'manual__2021-12-01T22:35:21.958244+00:00', '--job-id', '92', '--raw', '--subdir', 'DAGS_FOLDER/test_dag.py', '--cfg-path', '/tmp/tmpjzllzuw7', '--error-file', '/tmp/tmplwnq3nm1']
[2021-12-01 22:35:23,316] {standard_task_runner.py:77} INFO - Job 92: Subtask check_s3_for_file_in_s3
[2021-12-01 22:35:23,350] {logging_mixin.py:109} INFO - Running <TaskInstance: my_sample_dag.check_s3_for_file_in_s3 manual__2021-12-01T22:35:21.958244+00:00 [running]> on host 2227579f6dd3
[2021-12-01 22:35:23,396] {taskinstance.py:1429} INFO - Exporting the following env vars:
AIRFLOW_CTX_DAG_OWNER=pipis
AIRFLOW_CTX_DAG_ID=my_sample_dag
AIRFLOW_CTX_TASK_ID=check_s3_for_file_in_s3
AIRFLOW_CTX_EXECUTION_DATE=2021-12-01T22:35:21.958244+00:00
AIRFLOW_CTX_DAG_RUN_ID=manual__2021-12-01T22:35:21.958244+00:00
[2021-12-01 22:35:23,396] {s3_key.py:96} INFO - Poking for key : s3://test/file-to-watch
[2021-12-01 22:35:23,397] {base_aws.py:401} INFO - Airflow Connection: aws_conn_id=minio_s3
[2021-12-01 22:35:23,405] {base_aws.py:177} INFO - Credentials retrieved from login
[2021-12-01 22:35:23,405] {base_aws.py:93} INFO - Creating session with aws_access_key_id=*** region_name=None
[2021-12-01 22:35:23,414] {base_aws.py:168} INFO - role_arn is None
[2021-12-01 22:35:23,415] {warnings.py:110} WARNING - /home/***/.local/lib/python3.7/site-packages/***/providers/amazon/aws/hooks/base_aws.py:494: DeprecationWarning: client_type is deprecated. Set client_type from class attribute.
  return self.get_client_type(self.client_type, region_name=self.region_name)

[2021-12-01 22:35:24,045] {taskinstance.py:1703} ERROR - Task failed with exception
Traceback (most recent call last):
  File "/home/airflow/.local/lib/python3.7/site-packages/airflow/models/taskinstance.py", line 1332, in _run_raw_task
    self._execute_task_with_callbacks(context)
  File "/home/airflow/.local/lib/python3.7/site-packages/airflow/models/taskinstance.py", line 1458, in _execute_task_with_callbacks
    result = self._execute_task(context, self.task)
  File "/home/airflow/.local/lib/python3.7/site-packages/airflow/models/taskinstance.py", line 1514, in _execute_task
    result = execute_callable(context=context)
  File "/home/airflow/.local/lib/python3.7/site-packages/airflow/sensors/base.py", line 234, in execute
    while not self.poke(context):
  File "/home/airflow/.local/lib/python3.7/site-packages/airflow/providers/amazon/aws/sensors/s3_key.py", line 98, in poke
    return self.get_hook().check_for_wildcard_key(self.bucket_key, self.bucket_name)
  File "/home/airflow/.local/lib/python3.7/site-packages/airflow/providers/amazon/aws/hooks/s3.py", line 62, in wrapper
    return func(*bound_args.args, **bound_args.kwargs)
  File "/home/airflow/.local/lib/python3.7/site-packages/airflow/providers/amazon/aws/hooks/s3.py", line 90, in wrapper
    return func(*bound_args.args, **bound_args.kwargs)
  File "/home/airflow/.local/lib/python3.7/site-packages/airflow/providers/amazon/aws/hooks/s3.py", line 435, in check_for_wildcard_key
    self.get_wildcard_key(wildcard_key=wildcard_key, bucket_name=bucket_name, delimiter=delimiter)
  File "/home/airflow/.local/lib/python3.7/site-packages/airflow/providers/amazon/aws/hooks/s3.py", line 62, in wrapper
    return func(*bound_args.args, **bound_args.kwargs)
  File "/home/airflow/.local/lib/python3.7/site-packages/airflow/providers/amazon/aws/hooks/s3.py", line 90, in wrapper
    return func(*bound_args.args, **bound_args.kwargs)
  File "/home/airflow/.local/lib/python3.7/site-packages/airflow/providers/amazon/aws/hooks/s3.py", line 457, in get_wildcard_key
    key_list = self.list_keys(bucket_name, prefix=prefix, delimiter=delimiter)
  File "/home/airflow/.local/lib/python3.7/site-packages/airflow/providers/amazon/aws/hooks/s3.py", line 62, in wrapper
    return func(*bound_args.args, **bound_args.kwargs)
  File "/home/airflow/.local/lib/python3.7/site-packages/airflow/providers/amazon/aws/hooks/s3.py", line 301, in list_keys
    for page in response:
  File "/home/airflow/.local/lib/python3.7/site-packages/botocore/paginate.py", line 255, in __iter__
    response = self._make_request(current_kwargs)
  File "/home/airflow/.local/lib/python3.7/site-packages/botocore/paginate.py", line 334, in _make_request
    return self._method(**current_kwargs)
  File "/home/airflow/.local/lib/python3.7/site-packages/botocore/client.py", line 388, in _api_call
    return self._make_api_call(operation_name, kwargs)
  File "/home/airflow/.local/lib/python3.7/site-packages/botocore/client.py", line 708, in _make_api_call
    raise error_class(parsed_response, operation_name)
botocore.exceptions.ClientError: An error occurred (InvalidAccessKeyId) when calling the ListObjectsV2 operation: The AWS Access Key Id you provided does not exist in our records.
[2021-12-01 22:35:24,058] {taskinstance.py:1280} INFO - Marking task as FAILED. dag_id=my_sample_dag, task_id=check_s3_for_file_in_s3, execution_date=20211201T223521, start_date=20211201T223523, end_date=20211201T223524
[2021-12-01 22:35:24,074] {standard_task_runner.py:91} ERROR - Failed to execute job 92 for task check_s3_for_file_in_s3
Traceback (most recent call last):
  File "/home/airflow/.local/lib/python3.7/site-packages/airflow/task/task_runner/standard_task_runner.py", line 85, in _start_by_fork
    args.func(args, dag=self.dag)
  File "/home/airflow/.local/lib/python3.7/site-packages/airflow/cli/cli_parser.py", line 48, in command
    return func(*args, **kwargs)
  File "/home/airflow/.local/lib/python3.7/site-packages/airflow/utils/cli.py", line 92, in wrapper
    return f(*args, **kwargs)
  File "/home/airflow/.local/lib/python3.7/site-packages/airflow/cli/commands/task_command.py", line 292, in task_run
    _run_task_by_selected_method(args, dag, ti)
  File "/home/airflow/.local/lib/python3.7/site-packages/airflow/cli/commands/task_command.py", line 107, in _run_task_by_selected_method
    _run_raw_task(args, ti)
  File "/home/airflow/.local/lib/python3.7/site-packages/airflow/cli/commands/task_command.py", line 184, in _run_raw_task
    error_file=args.error_file,
  File "/home/airflow/.local/lib/python3.7/site-packages/airflow/utils/session.py", line 70, in wrapper
    return func(*args, session=session, **kwargs)
  File "/home/airflow/.local/lib/python3.7/site-packages/airflow/models/taskinstance.py", line 1332, in _run_raw_task
    self._execute_task_with_callbacks(context)
  File "/home/airflow/.local/lib/python3.7/site-packages/airflow/models/taskinstance.py", line 1458, in _execute_task_with_callbacks
    result = self._execute_task(context, self.task)
  File "/home/airflow/.local/lib/python3.7/site-packages/airflow/models/taskinstance.py", line 1514, in _execute_task
    result = execute_callable(context=context)
  File "/home/airflow/.local/lib/python3.7/site-packages/airflow/sensors/base.py", line 234, in execute
    while not self.poke(context):
  File "/home/airflow/.local/lib/python3.7/site-packages/airflow/providers/amazon/aws/sensors/s3_key.py", line 98, in poke
    return self.get_hook().check_for_wildcard_key(self.bucket_key, self.bucket_name)
  File "/home/airflow/.local/lib/python3.7/site-packages/airflow/providers/amazon/aws/hooks/s3.py", line 62, in wrapper
    return func(*bound_args.args, **bound_args.kwargs)
  File "/home/airflow/.local/lib/python3.7/site-packages/airflow/providers/amazon/aws/hooks/s3.py", line 90, in wrapper
    return func(*bound_args.args, **bound_args.kwargs)
  File "/home/airflow/.local/lib/python3.7/site-packages/airflow/providers/amazon/aws/hooks/s3.py", line 435, in check_for_wildcard_key
    self.get_wildcard_key(wildcard_key=wildcard_key, bucket_name=bucket_name, delimiter=delimiter)
  File "/home/airflow/.local/lib/python3.7/site-packages/airflow/providers/amazon/aws/hooks/s3.py", line 62, in wrapper
    return func(*bound_args.args, **bound_args.kwargs)
  File "/home/airflow/.local/lib/python3.7/site-packages/airflow/providers/amazon/aws/hooks/s3.py", line 90, in wrapper
    return func(*bound_args.args, **bound_args.kwargs)
  File "/home/airflow/.local/lib/python3.7/site-packages/airflow/providers/amazon/aws/hooks/s3.py", line 457, in get_wildcard_key
    key_list = self.list_keys(bucket_name, prefix=prefix, delimiter=delimiter)
  File "/home/airflow/.local/lib/python3.7/site-packages/airflow/providers/amazon/aws/hooks/s3.py", line 62, in wrapper
    return func(*bound_args.args, **bound_args.kwargs)
  File "/home/airflow/.local/lib/python3.7/site-packages/airflow/providers/amazon/aws/hooks/s3.py", line 301, in list_keys
    for page in response:
  File "/home/airflow/.local/lib/python3.7/site-packages/botocore/paginate.py", line 255, in __iter__
    response = self._make_request(current_kwargs)
  File "/home/airflow/.local/lib/python3.7/site-packages/botocore/paginate.py", line 334, in _make_request
    return self._method(**current_kwargs)
  File "/home/airflow/.local/lib/python3.7/site-packages/botocore/client.py", line 388, in _api_call
    return self._make_api_call(operation_name, kwargs)
  File "/home/airflow/.local/lib/python3.7/site-packages/botocore/client.py", line 708, in _make_api_call
    raise error_class(parsed_response, operation_name)
botocore.exceptions.ClientError: An error occurred (InvalidAccessKeyId) when calling the ListObjectsV2 operation: The AWS Access Key Id you provided does not exist in our records.
[2021-12-01 22:35:24,090] {local_task_job.py:154} INFO - Task exited with return code 1
[2021-12-01 22:35:24,119] {local_task_job.py:264} INFO - 0 downstream tasks scheduled from follow-on schedule check
