[2021-12-01 14:30:41,027] {taskinstance.py:1035} INFO - Dependencies all met for <TaskInstance: FrequencyCount.init scheduled__2021-11-30T14:25:19.414952+00:00 [queued]>
[2021-12-01 14:30:41,037] {taskinstance.py:1035} INFO - Dependencies all met for <TaskInstance: FrequencyCount.init scheduled__2021-11-30T14:25:19.414952+00:00 [queued]>
[2021-12-01 14:30:41,037] {taskinstance.py:1241} INFO - 
--------------------------------------------------------------------------------
[2021-12-01 14:30:41,037] {taskinstance.py:1242} INFO - Starting attempt 2 of 3
[2021-12-01 14:30:41,037] {taskinstance.py:1243} INFO - 
--------------------------------------------------------------------------------
[2021-12-01 14:30:41,048] {taskinstance.py:1262} INFO - Executing <Task(InitOperator): init> on 2021-11-30 14:25:19.414952+00:00
[2021-12-01 14:30:41,053] {standard_task_runner.py:52} INFO - Started process 8390 to run task
[2021-12-01 14:30:41,056] {standard_task_runner.py:76} INFO - Running: ['***', 'tasks', 'run', 'FrequencyCount', 'init', 'scheduled__2021-11-30T14:25:19.414952+00:00', '--job-id', '28', '--raw', '--subdir', 'DAGS_FOLDER/mapred.py', '--cfg-path', '/tmp/tmp1_ql1kdm', '--error-file', '/tmp/tmpq99or0p_']
[2021-12-01 14:30:41,056] {standard_task_runner.py:77} INFO - Job 28: Subtask init
[2021-12-01 14:30:41,099] {logging_mixin.py:109} INFO - Running <TaskInstance: FrequencyCount.init scheduled__2021-11-30T14:25:19.414952+00:00 [running]> on host 9d3ab7398319
[2021-12-01 14:30:41,145] {taskinstance.py:1429} INFO - Exporting the following env vars:
AIRFLOW_CTX_DAG_OWNER=***
AIRFLOW_CTX_DAG_ID=FrequencyCount
AIRFLOW_CTX_TASK_ID=init
AIRFLOW_CTX_EXECUTION_DATE=2021-11-30T14:25:19.414952+00:00
AIRFLOW_CTX_DAG_RUN_ID=scheduled__2021-11-30T14:25:19.414952+00:00
[2021-12-01 14:30:41,155] {logging_mixin.py:109} INFO - Directory b'***-worker.pid\n***.cfg\ndags\nlogs\nplugins\nwebserver_config.py\n'
[2021-12-01 14:30:41,156] {taskinstance.py:1703} ERROR - Task failed with exception
Traceback (most recent call last):
  File "/home/airflow/.local/lib/python3.7/site-packages/airflow/models/taskinstance.py", line 1332, in _run_raw_task
    self._execute_task_with_callbacks(context)
  File "/home/airflow/.local/lib/python3.7/site-packages/airflow/models/taskinstance.py", line 1458, in _execute_task_with_callbacks
    result = self._execute_task(context, self.task)
  File "/home/airflow/.local/lib/python3.7/site-packages/airflow/models/taskinstance.py", line 1514, in _execute_task
    result = execute_callable(context=context)
  File "/opt/airflow/plugins/init_operator.py", line 49, in execute
    with open(self.data_path, "r") as file:
FileNotFoundError: [Errno 2] No such file or directory: './dags/tweets.csv'
[2021-12-01 14:30:41,168] {taskinstance.py:1280} INFO - Marking task as UP_FOR_RETRY. dag_id=FrequencyCount, task_id=init, execution_date=20211130T142519, start_date=20211201T143041, end_date=20211201T143041
[2021-12-01 14:30:41,179] {standard_task_runner.py:91} ERROR - Failed to execute job 28 for task init
Traceback (most recent call last):
  File "/home/airflow/.local/lib/python3.7/site-packages/airflow/task/task_runner/standard_task_runner.py", line 85, in _start_by_fork
    args.func(args, dag=self.dag)
  File "/home/airflow/.local/lib/python3.7/site-packages/airflow/cli/cli_parser.py", line 48, in command
    return func(*args, **kwargs)
  File "/home/airflow/.local/lib/python3.7/site-packages/airflow/utils/cli.py", line 92, in wrapper
    return f(*args, **kwargs)
  File "/home/airflow/.local/lib/python3.7/site-packages/airflow/cli/commands/task_command.py", line 292, in task_run
    _run_task_by_selected_method(args, dag, ti)
  File "/home/airflow/.local/lib/python3.7/site-packages/airflow/cli/commands/task_command.py", line 107, in _run_task_by_selected_method
    _run_raw_task(args, ti)
  File "/home/airflow/.local/lib/python3.7/site-packages/airflow/cli/commands/task_command.py", line 184, in _run_raw_task
    error_file=args.error_file,
  File "/home/airflow/.local/lib/python3.7/site-packages/airflow/utils/session.py", line 70, in wrapper
    return func(*args, session=session, **kwargs)
  File "/home/airflow/.local/lib/python3.7/site-packages/airflow/models/taskinstance.py", line 1332, in _run_raw_task
    self._execute_task_with_callbacks(context)
  File "/home/airflow/.local/lib/python3.7/site-packages/airflow/models/taskinstance.py", line 1458, in _execute_task_with_callbacks
    result = self._execute_task(context, self.task)
  File "/home/airflow/.local/lib/python3.7/site-packages/airflow/models/taskinstance.py", line 1514, in _execute_task
    result = execute_callable(context=context)
  File "/opt/airflow/plugins/init_operator.py", line 49, in execute
    with open(self.data_path, "r") as file:
FileNotFoundError: [Errno 2] No such file or directory: './dags/tweets.csv'
[2021-12-01 14:30:41,188] {local_task_job.py:154} INFO - Task exited with return code 1
[2021-12-01 14:30:41,241] {local_task_job.py:264} INFO - 0 downstream tasks scheduled from follow-on schedule check
