[2021-12-01 14:50:53,600] {taskinstance.py:1035} INFO - Dependencies all met for <TaskInstance: FrequencyCount.init manual__2021-12-01T14:50:52.095578+00:00 [queued]>
[2021-12-01 14:50:53,610] {taskinstance.py:1035} INFO - Dependencies all met for <TaskInstance: FrequencyCount.init manual__2021-12-01T14:50:52.095578+00:00 [queued]>
[2021-12-01 14:50:53,610] {taskinstance.py:1241} INFO - 
--------------------------------------------------------------------------------
[2021-12-01 14:50:53,611] {taskinstance.py:1242} INFO - Starting attempt 1 of 2
[2021-12-01 14:50:53,611] {taskinstance.py:1243} INFO - 
--------------------------------------------------------------------------------
[2021-12-01 14:50:53,621] {taskinstance.py:1262} INFO - Executing <Task(InitOperator): init> on 2021-12-01 14:50:52.095578+00:00
[2021-12-01 14:50:53,626] {standard_task_runner.py:52} INFO - Started process 116 to run task
[2021-12-01 14:50:53,629] {standard_task_runner.py:76} INFO - Running: ['***', 'tasks', 'run', 'FrequencyCount', 'init', 'manual__2021-12-01T14:50:52.095578+00:00', '--job-id', '43', '--raw', '--subdir', 'DAGS_FOLDER/mapred.py', '--cfg-path', '/tmp/tmpayr_gt4g', '--error-file', '/tmp/tmpsdi91j6w']
[2021-12-01 14:50:53,629] {standard_task_runner.py:77} INFO - Job 43: Subtask init
[2021-12-01 14:50:53,661] {logging_mixin.py:109} INFO - Running <TaskInstance: FrequencyCount.init manual__2021-12-01T14:50:52.095578+00:00 [running]> on host 00cc1a67608d
[2021-12-01 14:50:53,703] {taskinstance.py:1429} INFO - Exporting the following env vars:
AIRFLOW_CTX_DAG_OWNER=***
AIRFLOW_CTX_DAG_ID=FrequencyCount
AIRFLOW_CTX_TASK_ID=init
AIRFLOW_CTX_EXECUTION_DATE=2021-12-01T14:50:52.095578+00:00
AIRFLOW_CTX_DAG_RUN_ID=manual__2021-12-01T14:50:52.095578+00:00
[2021-12-01 14:50:53,714] {logging_mixin.py:109} INFO - Directory b'***-worker.pid\n***.cfg\ndags\nlogs\nplugins\nwebserver_config.py\n'
[2021-12-01 14:50:53,714] {taskinstance.py:1703} ERROR - Task failed with exception
Traceback (most recent call last):
  File "/home/airflow/.local/lib/python3.7/site-packages/airflow/models/taskinstance.py", line 1332, in _run_raw_task
    self._execute_task_with_callbacks(context)
  File "/home/airflow/.local/lib/python3.7/site-packages/airflow/models/taskinstance.py", line 1458, in _execute_task_with_callbacks
    result = self._execute_task(context, self.task)
  File "/home/airflow/.local/lib/python3.7/site-packages/airflow/models/taskinstance.py", line 1514, in _execute_task
    result = execute_callable(context=context)
  File "/opt/airflow/plugins/init_operator.py", line 49, in execute
    with open(self.data_path, "r") as file:
FileNotFoundError: [Errno 2] No such file or directory: './tweets.csv'
[2021-12-01 14:50:53,726] {taskinstance.py:1280} INFO - Marking task as UP_FOR_RETRY. dag_id=FrequencyCount, task_id=init, execution_date=20211201T145052, start_date=20211201T145053, end_date=20211201T145053
[2021-12-01 14:50:53,738] {standard_task_runner.py:91} ERROR - Failed to execute job 43 for task init
Traceback (most recent call last):
  File "/home/airflow/.local/lib/python3.7/site-packages/airflow/task/task_runner/standard_task_runner.py", line 85, in _start_by_fork
    args.func(args, dag=self.dag)
  File "/home/airflow/.local/lib/python3.7/site-packages/airflow/cli/cli_parser.py", line 48, in command
    return func(*args, **kwargs)
  File "/home/airflow/.local/lib/python3.7/site-packages/airflow/utils/cli.py", line 92, in wrapper
    return f(*args, **kwargs)
  File "/home/airflow/.local/lib/python3.7/site-packages/airflow/cli/commands/task_command.py", line 292, in task_run
    _run_task_by_selected_method(args, dag, ti)
  File "/home/airflow/.local/lib/python3.7/site-packages/airflow/cli/commands/task_command.py", line 107, in _run_task_by_selected_method
    _run_raw_task(args, ti)
  File "/home/airflow/.local/lib/python3.7/site-packages/airflow/cli/commands/task_command.py", line 184, in _run_raw_task
    error_file=args.error_file,
  File "/home/airflow/.local/lib/python3.7/site-packages/airflow/utils/session.py", line 70, in wrapper
    return func(*args, session=session, **kwargs)
  File "/home/airflow/.local/lib/python3.7/site-packages/airflow/models/taskinstance.py", line 1332, in _run_raw_task
    self._execute_task_with_callbacks(context)
  File "/home/airflow/.local/lib/python3.7/site-packages/airflow/models/taskinstance.py", line 1458, in _execute_task_with_callbacks
    result = self._execute_task(context, self.task)
  File "/home/airflow/.local/lib/python3.7/site-packages/airflow/models/taskinstance.py", line 1514, in _execute_task
    result = execute_callable(context=context)
  File "/opt/airflow/plugins/init_operator.py", line 49, in execute
    with open(self.data_path, "r") as file:
FileNotFoundError: [Errno 2] No such file or directory: './tweets.csv'
[2021-12-01 14:50:53,760] {local_task_job.py:154} INFO - Task exited with return code 1
[2021-12-01 14:50:53,816] {local_task_job.py:264} INFO - 0 downstream tasks scheduled from follow-on schedule check
